2020-11-24 19:13:11,927 (util.py:75 PollingThread) ERROR - TeleBot: "ConnectionError occurred, args=(ProtocolError('Connection aborted.', ConnectionResetError(10054, 'Удаленный хост принудительно разорвал существующее подключение', None, 10054, None)),)
Traceback (most recent call last):
  File "C:\Users\s.chepinoga\PycharmProjects\telebot\venv\lib\site-packages\urllib3\connectionpool.py", line 670, in urlopen
    httplib_response = self._make_request(
  File "C:\Users\s.chepinoga\PycharmProjects\telebot\venv\lib\site-packages\urllib3\connectionpool.py", line 426, in _make_request
    six.raise_from(e, None)
  File "<string>", line 3, in raise_from
  File "C:\Users\s.chepinoga\PycharmProjects\telebot\venv\lib\site-packages\urllib3\connectionpool.py", line 421, in _make_request
    httplib_response = conn.getresponse()
  File "C:\Users\s.chepinoga\AppData\Local\Programs\Python\Python38-32\lib\http\client.py", line 1347, in getresponse
    response.begin()
  File "C:\Users\s.chepinoga\AppData\Local\Programs\Python\Python38-32\lib\http\client.py", line 307, in begin
    version, status, reason = self._read_status()
  File "C:\Users\s.chepinoga\AppData\Local\Programs\Python\Python38-32\lib\http\client.py", line 268, in _read_status
    line = str(self.fp.readline(_MAXLINE + 1), "iso-8859-1")
  File "C:\Users\s.chepinoga\AppData\Local\Programs\Python\Python38-32\lib\socket.py", line 669, in readinto
    return self._sock.recv_into(b)
  File "C:\Users\s.chepinoga\AppData\Local\Programs\Python\Python38-32\lib\ssl.py", line 1241, in recv_into
    return self.read(nbytes, buffer)
  File "C:\Users\s.chepinoga\AppData\Local\Programs\Python\Python38-32\lib\ssl.py", line 1099, in read
    return self._sslobj.read(len, buffer)
ConnectionResetError: [WinError 10054] Удаленный хост принудительно разорвал существующее подключение

During handling of the above exception, another exception occurred:

Traceback (most recent call last):
  File "C:\Users\s.chepinoga\PycharmProjects\telebot\venv\lib\site-packages\requests\adapters.py", line 439, in send
    resp = conn.urlopen(
  File "C:\Users\s.chepinoga\PycharmProjects\telebot\venv\lib\site-packages\urllib3\connectionpool.py", line 726, in urlopen
    retries = retries.increment(
  File "C:\Users\s.chepinoga\PycharmProjects\telebot\venv\lib\site-packages\urllib3\util\retry.py", line 403, in increment
    raise six.reraise(type(error), error, _stacktrace)
  File "C:\Users\s.chepinoga\PycharmProjects\telebot\venv\lib\site-packages\urllib3\packages\six.py", line 734, in reraise
    raise value.with_traceback(tb)
  File "C:\Users\s.chepinoga\PycharmProjects\telebot\venv\lib\site-packages\urllib3\connectionpool.py", line 670, in urlopen
    httplib_response = self._make_request(
  File "C:\Users\s.chepinoga\PycharmProjects\telebot\venv\lib\site-packages\urllib3\connectionpool.py", line 426, in _make_request
    six.raise_from(e, None)
  File "<string>", line 3, in raise_from
  File "C:\Users\s.chepinoga\PycharmProjects\telebot\venv\lib\site-packages\urllib3\connectionpool.py", line 421, in _make_request
    httplib_response = conn.getresponse()
  File "C:\Users\s.chepinoga\AppData\Local\Programs\Python\Python38-32\lib\http\client.py", line 1347, in getresponse
    response.begin()
  File "C:\Users\s.chepinoga\AppData\Local\Programs\Python\Python38-32\lib\http\client.py", line 307, in begin
    version, status, reason = self._read_status()
  File "C:\Users\s.chepinoga\AppData\Local\Programs\Python\Python38-32\lib\http\client.py", line 268, in _read_status
    line = str(self.fp.readline(_MAXLINE + 1), "iso-8859-1")
  File "C:\Users\s.chepinoga\AppData\Local\Programs\Python\Python38-32\lib\socket.py", line 669, in readinto
    return self._sock.recv_into(b)
  File "C:\Users\s.chepinoga\AppData\Local\Programs\Python\Python38-32\lib\ssl.py", line 1241, in recv_into
    return self.read(nbytes, buffer)
  File "C:\Users\s.chepinoga\AppData\Local\Programs\Python\Python38-32\lib\ssl.py", line 1099, in read
    return self._sslobj.read(len, buffer)
urllib3.exceptions.ProtocolError: ('Connection aborted.', ConnectionResetError(10054, 'Удаленный хост принудительно разорвал существующее подключение', None, 10054, None))

During handling of the above exception, another exception occurred:

Traceback (most recent call last):
  File "C:\Users\s.chepinoga\PycharmProjects\telebot\venv\lib\site-packages\telebot\util.py", line 69, in run
    task(*args, **kwargs)
  File "C:\Users\s.chepinoga\PycharmProjects\telebot\venv\lib\site-packages\telebot\__init__.py", line 285, in __retrieve_updates
    updates = self.get_updates(offset=(self.last_update_id + 1), timeout=timeout)
  File "C:\Users\s.chepinoga\PycharmProjects\telebot\venv\lib\site-packages\telebot\__init__.py", line 255, in get_updates
    json_updates = apihelper.get_updates(self.token, offset, limit, timeout, allowed_updates)
  File "C:\Users\s.chepinoga\PycharmProjects\telebot\venv\lib\site-packages\telebot\apihelper.py", line 241, in get_updates
    return _make_request(token, method_url, params=payload)
  File "C:\Users\s.chepinoga\PycharmProjects\telebot\venv\lib\site-packages\telebot\apihelper.py", line 102, in _make_request
    result = _get_req_session().request(
  File "C:\Users\s.chepinoga\PycharmProjects\telebot\venv\lib\site-packages\requests\sessions.py", line 530, in request
    resp = self.send(prep, **send_kwargs)
  File "C:\Users\s.chepinoga\PycharmProjects\telebot\venv\lib\site-packages\requests\sessions.py", line 643, in send
    r = adapter.send(request, **kwargs)
  File "C:\Users\s.chepinoga\PycharmProjects\telebot\venv\lib\site-packages\requests\adapters.py", line 498, in send
    raise ConnectionError(err, request=request)
requests.exceptions.ConnectionError: ('Connection aborted.', ConnectionResetError(10054, 'Удаленный хост принудительно разорвал существующее подключение', None, 10054, None))
"
Traceback (most recent call last):
  File "C:\Users\s.chepinoga\PycharmProjects\telebot\venv\lib\site-packages\urllib3\connectionpool.py", line 670, in urlopen
    httplib_response = self._make_request(
  File "C:\Users\s.chepinoga\PycharmProjects\telebot\venv\lib\site-packages\urllib3\connectionpool.py", line 426, in _make_request
    six.raise_from(e, None)
  File "<string>", line 3, in raise_from
  File "C:\Users\s.chepinoga\PycharmProjects\telebot\venv\lib\site-packages\urllib3\connectionpool.py", line 421, in _make_request
    httplib_response = conn.getresponse()
  File "C:\Users\s.chepinoga\AppData\Local\Programs\Python\Python38-32\lib\http\client.py", line 1347, in getresponse
    response.begin()
  File "C:\Users\s.chepinoga\AppData\Local\Programs\Python\Python38-32\lib\http\client.py", line 307, in begin
    version, status, reason = self._read_status()
  File "C:\Users\s.chepinoga\AppData\Local\Programs\Python\Python38-32\lib\http\client.py", line 268, in _read_status
    line = str(self.fp.readline(_MAXLINE + 1), "iso-8859-1")
  File "C:\Users\s.chepinoga\AppData\Local\Programs\Python\Python38-32\lib\socket.py", line 669, in readinto
    return self._sock.recv_into(b)
  File "C:\Users\s.chepinoga\AppData\Local\Programs\Python\Python38-32\lib\ssl.py", line 1241, in recv_into
    return self.read(nbytes, buffer)
  File "C:\Users\s.chepinoga\AppData\Local\Programs\Python\Python38-32\lib\ssl.py", line 1099, in read
    return self._sslobj.read(len, buffer)
ConnectionResetError: [WinError 10054] Удаленный хост принудительно разорвал существующее подключение

During handling of the above exception, another exception occurred:

Traceback (most recent call last):
  File "C:\Users\s.chepinoga\PycharmProjects\telebot\venv\lib\site-packages\requests\adapters.py", line 439, in send
    resp = conn.urlopen(
  File "C:\Users\s.chepinoga\PycharmProjects\telebot\venv\lib\site-packages\urllib3\connectionpool.py", line 726, in urlopen
    retries = retries.increment(
  File "C:\Users\s.chepinoga\PycharmProjects\telebot\venv\lib\site-packages\urllib3\util\retry.py", line 403, in increment
    raise six.reraise(type(error), error, _stacktrace)
  File "C:\Users\s.chepinoga\PycharmProjects\telebot\venv\lib\site-packages\urllib3\packages\six.py", line 734, in reraise
    raise value.with_traceback(tb)
  File "C:\Users\s.chepinoga\PycharmProjects\telebot\venv\lib\site-packages\urllib3\connectionpool.py", line 670, in urlopen
    httplib_response = self._make_request(
  File "C:\Users\s.chepinoga\PycharmProjects\telebot\venv\lib\site-packages\urllib3\connectionpool.py", line 426, in _make_request
    six.raise_from(e, None)
  File "<string>", line 3, in raise_from
  File "C:\Users\s.chepinoga\PycharmProjects\telebot\venv\lib\site-packages\urllib3\connectionpool.py", line 421, in _make_request
    httplib_response = conn.getresponse()
  File "C:\Users\s.chepinoga\AppData\Local\Programs\Python\Python38-32\lib\http\client.py", line 1347, in getresponse
    response.begin()
  File "C:\Users\s.chepinoga\AppData\Local\Programs\Python\Python38-32\lib\http\client.py", line 307, in begin
    version, status, reason = self._read_status()
  File "C:\Users\s.chepinoga\AppData\Local\Programs\Python\Python38-32\lib\http\client.py", line 268, in _read_status
    line = str(self.fp.readline(_MAXLINE + 1), "iso-8859-1")
  File "C:\Users\s.chepinoga\AppData\Local\Programs\Python\Python38-32\lib\socket.py", line 669, in readinto
    return self._sock.recv_into(b)
  File "C:\Users\s.chepinoga\AppData\Local\Programs\Python\Python38-32\lib\ssl.py", line 1241, in recv_into
    return self.read(nbytes, buffer)
  File "C:\Users\s.chepinoga\AppData\Local\Programs\Python\Python38-32\lib\ssl.py", line 1099, in read
    return self._sslobj.read(len, buffer)
urllib3.exceptions.ProtocolError: ('Connection aborted.', ConnectionResetError(10054, 'Удаленный хост принудительно разорвал существующее подключение', None, 10054, None))

During handling of the above exception, another exception occurred:

Traceback (most recent call last):
  File "C:/Users/s.chepinoga/PycharmProjects/telebot/bot_new.py", line 85, in <module>
    bot.polling()
  File "C:\Users\s.chepinoga\PycharmProjects\telebot\venv\lib\site-packages\telebot\__init__.py", line 427, in polling
    self.__threaded_polling(none_stop, interval, timeout)
  File "C:\Users\s.chepinoga\PycharmProjects\telebot\venv\lib\site-packages\telebot\__init__.py", line 450, in __threaded_polling
    polling_thread.raise_exceptions()
  File "C:\Users\s.chepinoga\PycharmProjects\telebot\venv\lib\site-packages\telebot\util.py", line 88, in raise_exceptions
    six.reraise(self.exc_info[0], self.exc_info[1], self.exc_info[2])
  File "C:\Users\s.chepinoga\PycharmProjects\telebot\venv\lib\site-packages\six.py", line 703, in reraise
    raise value
  File "C:\Users\s.chepinoga\PycharmProjects\telebot\venv\lib\site-packages\telebot\util.py", line 69, in run
    task(*args, **kwargs)
  File "C:\Users\s.chepinoga\PycharmProjects\telebot\venv\lib\site-packages\telebot\__init__.py", line 285, in __retrieve_updates
    updates = self.get_updates(offset=(self.last_update_id + 1), timeout=timeout)
  File "C:\Users\s.chepinoga\PycharmProjects\telebot\venv\lib\site-packages\telebot\__init__.py", line 255, in get_updates
    json_updates = apihelper.get_updates(self.token, offset, limit, timeout, allowed_updates)
  File "C:\Users\s.chepinoga\PycharmProjects\telebot\venv\lib\site-packages\telebot\apihelper.py", line 241, in get_updates
    return _make_request(token, method_url, params=payload)
  File "C:\Users\s.chepinoga\PycharmProjects\telebot\venv\lib\site-packages\telebot\apihelper.py", line 102, in _make_request
    result = _get_req_session().request(
  File "C:\Users\s.chepinoga\PycharmProjects\telebot\venv\lib\site-packages\requests\sessions.py", line 530, in request
    resp = self.send(prep, **send_kwargs)
  File "C:\Users\s.chepinoga\PycharmProjects\telebot\venv\lib\site-packages\requests\sessions.py", line 643, in send
    r = adapter.send(request, **kwargs)
  File "C:\Users\s.chepinoga\PycharmProjects\telebot\venv\lib\site-packages\requests\adapters.py", line 498, in send
    raise ConnectionError(err, request=request)
requests.exceptions.ConnectionError: ('Connection aborted.', ConnectionResetError(10054, 'Удаленный хост принудительно разорвал существующее подключение', None, 10054, None))

Process finished with exit code 1
